Traceback (most recent call last):
  File "/usr/lib/python3/dist-packages/jupyter_cache/executors/utils.py", line 58, in single_nb_execution
    executenb(
  File "/usr/local/lib/python3.10/dist-packages/nbclient/client.py", line 1314, in execute
    return NotebookClient(nb=nb, resources=resources, km=km, **kwargs).execute()
  File "/usr/local/lib/python3.10/dist-packages/jupyter_core/utils/__init__.py", line 165, in wrapped
    return loop.run_until_complete(inner)
  File "/usr/lib/python3.10/asyncio/base_events.py", line 649, in run_until_complete
    return future.result()
  File "/usr/local/lib/python3.10/dist-packages/nbclient/client.py", line 709, in async_execute
    await self.async_execute_cell(
  File "/usr/local/lib/python3.10/dist-packages/nbclient/client.py", line 1062, in async_execute_cell
    await self._check_raise_for_error(cell, cell_index, exec_reply)
  File "/usr/local/lib/python3.10/dist-packages/nbclient/client.py", line 918, in _check_raise_for_error
    raise CellExecutionError.from_cell_and_msg(cell, exec_reply_content)
nbclient.exceptions.CellExecutionError: An error occurred while executing the following cell:
------------------
import pyvista
pyvista.start_xvfb()
from dolfinx.plot import create_vtk_mesh
topology, cell_types, x = create_vtk_mesh(mesh, mesh.topology.dim)
grid = pyvista.UnstructuredGrid(topology, cell_types, x)
num_local_cells = mesh.topology.index_map(mesh.topology.dim).size_local
# grid.cell_data["Marker"] = ct.values[ct.indices<num_local_cells]
# grid.set_active_scalars("Marker")

p = pyvista.Plotter(window_size=[800, 800])
p.add_mesh(grid, show_edges=True)
p.view_xy()
p.show()
------------------


[0;31m---------------------------------------------------------------------------[0m
[0;31mImportError[0m                               Traceback (most recent call last)
Cell [0;32mIn[13], line 3[0m
[1;32m      1[0m [38;5;28;01mimport[39;00m [38;5;21;01mpyvista[39;00m
[1;32m      2[0m pyvista[38;5;241m.[39mstart_xvfb()
[0;32m----> 3[0m [38;5;28;01mfrom[39;00m [38;5;21;01mdolfinx[39;00m[38;5;21;01m.[39;00m[38;5;21;01mplot[39;00m [38;5;28;01mimport[39;00m create_vtk_mesh
[1;32m      4[0m topology, cell_types, x [38;5;241m=[39m create_vtk_mesh(mesh, mesh[38;5;241m.[39mtopology[38;5;241m.[39mdim)
[1;32m      5[0m grid [38;5;241m=[39m pyvista[38;5;241m.[39mUnstructuredGrid(topology, cell_types, x)

[0;31mImportError[0m: cannot import name 'create_vtk_mesh' from 'dolfinx.plot' (/usr/local/dolfinx-real/lib/python3.10/dist-packages/dolfinx/plot.py)

