Traceback (most recent call last):
  File "/usr/lib/python3/dist-packages/jupyter_cache/executors/utils.py", line 58, in single_nb_execution
    executenb(
  File "/usr/local/lib/python3.10/dist-packages/nbclient/client.py", line 1314, in execute
    return NotebookClient(nb=nb, resources=resources, km=km, **kwargs).execute()
  File "/usr/local/lib/python3.10/dist-packages/jupyter_core/utils/__init__.py", line 165, in wrapped
    return loop.run_until_complete(inner)
  File "/usr/lib/python3.10/asyncio/base_events.py", line 649, in run_until_complete
    return future.result()
  File "/usr/local/lib/python3.10/dist-packages/nbclient/client.py", line 709, in async_execute
    await self.async_execute_cell(
  File "/usr/local/lib/python3.10/dist-packages/nbclient/client.py", line 1062, in async_execute_cell
    await self._check_raise_for_error(cell, cell_index, exec_reply)
  File "/usr/local/lib/python3.10/dist-packages/nbclient/client.py", line 918, in _check_raise_for_error
    raise CellExecutionError.from_cell_and_msg(cell, exec_reply_content)
nbclient.exceptions.CellExecutionError: An error occurred while executing the following cell:
------------------
mt_0 = df.mesh.create_meshtags(mesh, mesh.topology.dim, cells_0)
------------------


[0;31m---------------------------------------------------------------------------[0m
[0;31mAttributeError[0m                            Traceback (most recent call last)
Cell [0;32mIn[6], line 1[0m
[0;32m----> 1[0m mt_0 [38;5;241m=[39m [43mdf[49m[38;5;241;43m.[39;49m[43mmesh[49m[38;5;241;43m.[39;49m[43mcreate_meshtags[49m(mesh, mesh[38;5;241m.[39mtopology[38;5;241m.[39mdim, cells_0)

[0;31mAttributeError[0m: module 'dolfinx.mesh' has no attribute 'create_meshtags'

